Workbook
Name UPDATE: 'Data Sheet'!$E$1

Sheet Dashboard
E1: Financial Dashboard
E2: THREE- STATEMENT FINANCIAL DASHBOARD
S5: =D15 -> 44651 | T5: =E15 -> 45016 | U5: =F15 -> 45382 | V5: =G15 -> 45747 | W5: =H15 -> 46112
R6: Sales | S6: ='Data Sheet'!G17 -> 4396.12 | T6: ='Data Sheet'!H17 -> 5158.25 | U6: ='Data Sheet'!I17 -> 5655.09 | V6: ='Data Sheet'!J17 -> 8104.49 | W6: ='Data Sheet'!K17 -> 9512.51
B7: 2026 Revenue | F7: FY2026 EBITDA | J7: FY2026 NET PROFIT | N7: NOPAT | R7: Gross Profit | S7: ='Historical Financial Statment'!J19 -> 3120.67 | T7: ='Historical Financial Statment'!K19 -> 3617.54 | U7: ='Historical Financial Statment'!L19 -> 3870.84 | V7: ='Historical Financial Statment'!M19 -> 5789.37 | W7: ='Historical Financial Statment'!N19 -> 7278.18
R8: EBITDA | S8: ='Historical Financial Statment'!J25 -> 2096.26 | T8: ='Historical Financial Statment'!K25 -> 2383.76 | U8: ='Historical Financial Statment'!L25 -> 2500.44 | V8: ='Historical Financial Statment'!M25 -> 3851.72 | W8: ='Historical Financial Statment'!N25 -> 5018.06
R9: EBT | S9: ='Historical Financial Statment'!J34 -> 1527.12 | T9: ='Historical Financial Statment'!K34 -> 1696.64 | U9: ='Historical Financial Statment'!L34 -> 1614.71 | V9: ='Historical Financial Statment'!M34 -> 2536.08 | W9: ='Historical Financial Statment'!N34 -> 3623.34
B10: ='Historical Financial Statment'!N13 -> 9512.51 | F10: ='Historical Financial Statment'!N25 -> 5018.06 | J10: ='Historical Financial Statment'!N40 -> 3468.86 | N10: ='Growth Rate'!O44 -> 2841.524 | R10: Net Profit | S10: ='Historical Financial Statment'!J40 -> 1381.94 | T10: ='Historical Financial Statment'!K40 -> 1560.94 | U10: ='Historical Financial Statment'!L40 -> 1529.74 | V10: ='Historical Financial Statment'!M40 -> 2452.66 | W10: ='Historical Financial Statment'!N40 -> 3468.86
B14: Financial Growth | J14: Key Ratios
B15: Metric | D15: ='Historical Financial Statment'!$J$11 -> 44651 | E15: ='Historical Financial Statment'!$K$11 -> 45016 | F15: ='Historical Financial Statment'!$L$11 -> 45382 | G15: ='Historical Financial Statment'!$M$11 -> 45747 | H15: ='Historical Financial Statment'!$N$11 -> 46112 | J15: Current Ratio | N15: ='Growth Rate'!O16/'Growth Rate'!O22 -> 0.68367838
B16: Sales | D16: ='Historical Financial Statment'!J13/'Historical Financial Statment'!I13-1 -> 0.32738302 | E16: ='Historical Financial Statment'!K13/'Historical Financial Statment'!J13-1 -> 0.17336424 | F16: ='Historical Financial Statment'!L13/'Historical Financial Statment'!K13-1 -> 0.096319488 | G16: ='Historical Financial Statment'!M13/'Historical Financial Statment'!L13-1 -> 0.43313192 | H16: ='Historical Financial Statment'!N13/'Historical Financial Statment'!M13-1 -> 0.17373333 | J16: Liquidity Ratio | N16: =('Growth Rate'!O16-'Historical Financial Statment'!N67)/'Growth Rate'!O22 -> 0.53513722
B17: Gross Profit | D17: ='Historical Financial Statment'!J19/'Historical Financial Statment'!I19-1 -> 0.29176963 | E17: ='Historical Financial Statment'!K19/'Historical Financial Statment'!J19-1 -> 0.15921901 | F17: ='Historical Financial Statment'!L19/'Historical Financial Statment'!K19-1 -> 0.070019958 | G17: ='Historical Financial Statment'!M19/'Historical Financial Statment'!L19-1 -> 0.49563661 | H17: ='Historical Financial Statment'!N19/'Historical Financial Statment'!M19-1 -> 0.2571627 | J17: ROE | N17: =('Historical Financial Statment'!N25-'Historical Financial Statment'!N31)/SUM('Historical Financial Statment'!N54:N55) -> 1.7710048
B18: EBITDA | D18: ='Historical Financial Statment'!J25/'Historical Financial Statment'!I25-1 -> 0.18554672 | E18: ='Historical Financial Statment'!K25/'Historical Financial Statment'!J25-1 -> 0.13714902 | F18: ='Historical Financial Statment'!L25/'Historical Financial Statment'!K25-1 -> 0.048947881 | G18: ='Historical Financial Statment'!M25/'Historical Financial Statment'!L25-1 -> 0.54041689 | H18: ='Historical Financial Statment'!N25/'Historical Financial Statment'!M25-1 -> 0.30281017 | J18: Return on Capital Employed | N18: =('Historical Financial Statment'!N34+'Historical Financial Statment'!N31)/SUM('Historical Financial Statment'!N54:N56) -> 0.63690245
B19: EBT | D19: ='Historical Financial Statment'!J34/'Historical Financial Statment'!I34-1 -> 0.24148023 | E19: ='Historical Financial Statment'!K34/'Historical Financial Statment'!J34-1 -> 0.11100634 | F19: ='Historical Financial Statment'!L34/'Historical Financial Statment'!K34-1 -> -0.048289561 | G19: ='Historical Financial Statment'!M34/'Historical Financial Statment'!L34-1 -> 0.5706102 | H19: ='Historical Financial Statment'!N34/'Historical Financial Statment'!M34-1 -> 0.42871676 | J19: Sustainable Growth | N19: =N17*'Historical Financial Statment'!N50 -> 1.7305799
B20: Net Profit | D20: ='Historical Financial Statment'!J40/'Historical Financial Statment'!I40-1 -> 0.19707561 | E20: ='Historical Financial Statment'!K40/'Historical Financial Statment'!J40-1 -> 0.12952805 | F20: ='Historical Financial Statment'!L40/'Historical Financial Statment'!K40-1 -> -0.019987956 | G20: ='Historical Financial Statment'!M40/'Historical Financial Statment'!L40-1 -> 0.60331821 | H20: ='Historical Financial Statment'!N40/'Historical Financial Statment'!M40-1 -> 0.41432567
J22: WACC | N22: =WACC!$L$45 -> 0.10176029
J25: GROWTH RATE | N25: ='Growth Rate'!O63 -> 0.12139764
J28: PV of FCFF | N28: ='DCF Valuation'!D30 -> 15729.612
J31: DCF VALUE | N31: ='DCF Valuation'!D41 -> 1399.7041

Sheet Instructions
C2: FINANCIAL MODELLING GUIDE & COLOUR CODING
D4: Understand the Purpose l | G4: Know the Purpose l | I4: Follow the Colour Conventions l
N6: 3. Colour Coding Convention
C7: 1. Purpose of This Workbook
C8: This workbook contain historical financial statement , financial analysis , financial forecasting, valuation | N8: Colour / Format | Q8: Meaning
C9: and equity analysis. This guide explains the purpose of each worksheet and the colour connection used
C10: throught the model | N10: Blue Font | Q10: Harcoded Inputs and mutually
Q11: entered data
C13: 2. Worksheet Guide | N13: Black Font | Q13: Formula and Calculations
C16: Sheet Name | H16: Purpose / Use
C19: 1 | D19: Dashboard | H19: Summaries key financial metrics, valuation results and performance through charts.
C21: 2 | D21: Data Sheet | H21: Contains raw company data used as a main source for financial analysis.
C23: 3 | D23: Data Collection | H23: Contain Raw Balance Sheet data for Calculation of net capex.
C25: 4 | D25: Comp Data | H25: Contain the raw comparable data of different peer companies for WACC calculation.
C27: 5 | D27: Historical Financial Statement | H27: Present Historical Financial Statement for analyse past performance of company.
C29: 6 | D29: WACC | H29: Calculate the Weighted Average Cost of Capital used as a calculative part to calculate Discounted Factor.
C31: 7 | D31: Growth Rate | H31: Calculate historical growth rate and supports future financial projects.
C33: 8 | D33: DCF Valuation | H33: Estimated the intrinsic Equity value of Company by using cash flow and discount.
C35: 9 | D35: Comp Value | H35: Estimated Equity value of Company by using Peer Companied Comparable data.
C37: 10 | D37: Football Field Analysis | H37: Compares values ranges obtained from different valuation methodologies.

Sheet Data Sheet
A1: COMPANY NAME | B1: JUBILANT FOODWORKS LTD | E1: =IF(B2<>B3, "A NEW VERSION OF THE WORKSHEET IS AVAILABLE", "")
A2: LATEST VERSION | B2: 2.1 | E2: PLEASE DO NOT MAKE ANY CHANGES TO THIS SHEET
A3: CURRENT VERSION | B3: 2.1
A5: META
A6: Number of shares | B6: =IF(B9>0, B9/B8, 0) -> 65.984528
A7: Face Value | B7: 2
A8: Current Price | B8: 422.05
A9: Market Capitalization | B9: 27848.77
A15: PROFIT & LOSS
A16: Report Date | B16: 42825 | C16: 43190 | D16: 43555 | E16: 43921 | F16: 44286 | G16: 44651 | H16: 45016 | I16: 45382 | J16: 45747 | K16: 46112
A17: Sales | B17: 2583.39 | C17: 3018.4 | D17: 3563.14 | E17: 3927.27 | F17: 3311.87 | G17: 4396.12 | H17: 5158.25 | I17: 5655.09 | J17: 8104.49 | K17: 9512.51
A18: Raw Material Cost | B18: 631.3 | C18: 767.43 | D18: 885.31 | E18: 984.5 | F18: 727.58 | G18: 993.65 | H18: 1253.47 | I18: 1346.85 | J18: 2266.62 | K18: 2693.67
A19: Change in Inventory | B19: 0.53 | C19: 1.47 | D19: -0.8 | E19: 1.03 | F19: 1.34 | G19: 3.75 | H19: 5.66 | I19: 5.76 | J19: 8.81 | K19: -16.7
A20: Power and Fuel | B20: 145.86 | C20: 160.31 | D20: 168.99 | E20: 172.62 | F20: 147.6 | G20: 200.66 | H20: 267.25 | I20: 309.61 | J20: 361.77
A21: Other Mfr. Exp | B21: 174.48 | C21: 188.89 | D21: 233.07 | E21: 246.25 | G21: 304.49 | H21: 365.27 | I21: 413.6 | J21: 557.01 | K21: 608.79
A22: Employee Cost | B22: 595.63 | C22: 615.21 | D22: 683.54 | E22: 797.84 | F22: 748.46 | G22: 770.3 | H22: 908.19 | I22: 1061.04 | J22: 1396.34 | K22: 1625.54
A23: Selling and admin | B23: 726.91 | C23: 769.62 | D23: 893.84 | E23: 744.27 | F23: 570.78 | G23: 914.89 | H23: 1082.63 | I23: 1268.54 | J23: 1823.47 | K23: 2108.68
A24: Other Expenses | B24: 65.17 | C24: 76.41 | D24: 94.97 | E24: 100.1 | F24: 76.85 | G24: 109.52 | H24: 151.15 | I24: 101.86 | J24: 114.18 | K24: 151.44
A25: Other Income | B25: -0.87 | C25: 21.17 | D25: 44.5 | E25: 37.58 | F25: 64.23 | G25: 26.04 | H25: 39.9 | I25: 211.41 | J25: 22.27 | K25: 91.35
A26: Depreciation | B26: 155.43 | C26: 160.11 | D26: 157.45 | E26: 352.28 | F26: 375.4 | G26: 393.05 | H26: 485.89 | I26: 597.96 | J26: 795.41 | K26: 958.74
A27: Interest | E27: 165.24 | F27: 162.7 | G27: 176.09 | H27: 201.23 | I27: 287.77 | J27: 520.23 | K27: 435.98
A28: Profit before tax | B28: 88.27 | C28: 303.06 | D28: 489.67 | E28: 402.78 | F28: 306.17 | G28: 563.26 | H28: 488.73 | I28: 485.03 | J28: 300.54 | K28: 598.72
A29: Tax | B29: 30.5 | C29: 106.83 | D29: 171.7 | E29: 123.99 | F29: 75.65 | G29: 145.18 | H29: 135.7 | I29: 84.97 | J29: 83.42 | K29: 154.48
A30: Net profit | B30: 57.77 | C30: 196.23 | D30: 319.79 | E30: 279.98 | F30: 231.67 | G30: 420.39 | H30: 353.2 | I30: 399.34 | J30: 210.76 | K30: 428.48
A31: Dividend Amount | B31: 16.49 | C31: 32.99 | D31: 65.98 | E31: 79.18 | F31: 79.18 | G31: 79.18 | H31: 79.18 | I31: 79.18 | J31: 79.18 | K31: 79.18
A40: Quarters
A41: Report Date | B41: 45382 | C41: 45473 | D41: 45565 | E41: 45657 | F41: 45747 | G41: 45838 | H41: 45930 | I41: 46022 | J41: 46112 | K41: 46203
A42: Sales | B42: 1573.8 | C42: 1933.06 | D42: 1954.72 | E42: 2150.76 | F42: 2095.02 | G42: 2260.86 | H42: 2340.15 | I42: 2429.19 | J42: 2499.47 | K42: 2569.65
A43: Expenses | B43: 1262.45 | C43: 1552.63 | D43: 1558.39 | E43: 1749.02 | F43: 1703.13 | G43: 1822.88 | H43: 1863.97 | I43: 1945.36 | J43: 2014.57 | K43: 2065.79
A44: Other Income | B44: 196.03 | C44: 14.35 | D44: 25.22 | E44: 6.44 | F44: 4.65 | G44: 18.88 | H44: 102.29 | I44: -17.97 | J44: 12.81 | K44: 19.59
A45: Depreciation | B45: 168.85 | C45: 183.54 | D45: 201.43 | E45: 207.83 | F45: 209.72 | G45: 220.18 | H45: 230.31 | I45: 246.79 | J45: 269.4 | K45: 255.03
A46: Interest | B46: 114.18 | C46: 134.39 | D46: 138.11 | E46: 133.44 | F46: 116.13 | G46: 110.69 | H46: 105.71 | I46: 103.08 | J46: 117.49 | K46: 120.27
A47: Profit before tax | B47: 224.35 | C47: 76.85 | D47: 82.01 | E47: 66.91 | F47: 70.69 | G47: 125.99 | H47: 242.45 | I47: 115.99 | J47: 110.82 | K47: 148.15
A48: Tax | B48: 16.11 | C48: 18.82 | D48: 15.47 | E48: 23.67 | F48: 21.36 | G48: 31.66 | H48: 47.86 | I48: 43.11 | J48: 28.4 | K48: 48.13
A49: Net profit | B49: 207.52 | C49: 55.8 | D49: 64.05 | E49: 42.91 | F49: 48.01 | G49: 91.76 | H49: 186.03 | I49: 70.9 | J49: 79.79 | K49: 97.24
A50: Operating Profit | B50: 311.35 | C50: 380.43 | D50: 396.33 | E50: 401.74 | F50: 391.89 | G50: 437.98 | H50: 476.18 | I50: 483.83 | J50: 484.9 | K50: 503.86
A55: BALANCE SHEET
A56: Report Date | B56: 42825 | C56: 43190 | D56: 43555 | E56: 43921 | F56: 44286 | G56: 44651 | H56: 45016 | I56: 45382 | J56: 45747 | K56: 46112
A57: Equity Share Capital | B57: 65.95 | C57: 65.98 | D57: 131.97 | E57: 131.97 | F57: 131.97 | G57: 131.97 | H57: 131.97 | I57: 131.97 | J57: 131.97 | K57: 131.97
A58: Reserves | B58: 739.35 | C58: 901.75 | D58: 1127.67 | E58: 990.06 | F58: 1294.86 | G58: 1813 | H58: 1905.82 | I58: 2038.67 | J58: 1970.78 | K58: 2160.13
...

Sheet COMP DATA
B2: S.No. | C2: Company | D2: CMP Rs. | E2: No. Eq. Shares Cr. | F2: Debt Rs.Cr. | G2: Mar Cap Rs.Cr. | H2: EV | I2: EBITDA | J2: Sales Rs.Cr. | K2: NP 12M Rs.Cr.
B3: 1 | C3: Jubilant Food. | D3: 422.1 | E3: 65.98 | F3: 4902.22 | G3: 27852.08 | H3: 32519.42 | I3: 2031.02 | J3: 9838.46 | K3: 449.93
B4: 2 | C4: Travel Food | D4: 1200.6 | E4: 13.17 | F4: 244.79 | G4: 15813.82 | H4: 15999.25 | I4: 854.83 | J4: 1724.96 | K4: 486.11
B5: 3 | C5: Devyani Intl. | D5: 121.5 | E5: 123.29 | F5: 3833.15 | G5: 14980.21 | H5: 18318.56 | I5: 948.37 | J5: 5835.03 | K5: -27.66
B6: 4 | C6: Westlife Food | D6: 581.3 | E6: 15.59 | F6: 1804.79 | G6: 9064.57 | H6: 10852.43 | I6: 375.65 | J6: 2703.57 | K6: 31.7
B7: 5 | C7: Restaurant Brand | D7: 92.32 | E7: 71.22 | F7: 1967 | G7: 6575.21 | H7: 8483.3 | I7: 402.11 | J7: 2947.53 | K7: -191.72
B8: 6 | C8: Sapphire Foods | D8: 196.5 | E8: 32.14 | F8: 1417.13 | G8: 6315.17 | H8: 7664.19 | I8: 527.48 | J8: 3239.45 | K8: -16.21
B9: 7 | C9: United Foodbrands | D9: 678.85 | E9: 3.91 | F9: 885.27 | G9: 2655.62 | H9: 3513.23 | I9: 230.9 | J9: 1467.63 | K9: -42.94

Sheet Data Collection
B2: Particulars | E2: 42795 | F2: 43160 | G2: 43525 | H2: 43891 | I2: 44256 | J2: 44621 | K2: 44986 | L2: 45352 | M2: 45717 | N2: 46082
B3: Equity Capital | E3: 66 | F3: 66 | G3: 132 | H3: 132 | I3: 132 | J3: 132 | K3: 132 | L3: 132 | M3: 132 | N3: 132
B4: Reserves | E4: 739 | F4: 902 | G4: 1128 | H4: 990 | I4: 1295 | J4: 1813 | K4: 1906 | L4: 2039 | M4: 1971 | N4: 2160
B5: Borrowings -
B6: Long term Borrowings | E6: 0 | F6: 0 | G6: 0 | H6: 0 | I6: 0 | J6: 120 | K6: 183 | L6: 1195 | M6: 1283 | N6: 340
B7: Short term Borrowings | E7: 0 | F7: 0 | G7: 0 | H7: 0 | I7: 0 | J7: 0 | K7: 0 | L7: 312 | M7: 219 | N7: 1406
B8: Lease Liabilities | E8: 0 | F8: 0 | G8: 0 | H8: 1670 | I8: 1620 | J8: 1986 | K8: 2371 | L8: 2700 | M8: 2870 | N8: 3157
B9: Other Borrowings | E9: 0 | F9: 0 | G9: 0 | H9: 0 | I9: 0 | J9: 0 | K9: 0 | L9: 0 | M9: 0 | N9: 0
B10: Other Liabilities -
B11: Non controlling int | E11: 0 | F11: 0 | G11: 3 | H11: 11 | I11: 9 | J11: 10 | K11: 0 | L11: 73 | M11: 80 | N11: 96
B12: Trade Payables | E12: 314 | F12: 389 | G12: 421 | H12: 447 | I12: 533 | J12: 537 | K12: 561 | L12: 790 | M12: 901 | N12: 1036
B13: Advance from Customers | E13: 0 | F13: 0 | G13: 0 | H13: 1 | I13: 2 | J13: 4 | K13: 4 | L13: 26 | M13: 20 | N13: 20
B14: Other liability items | E14: 171 | F14: 140 | G14: 173 | H14: 119 | I14: 176 | J14: 180 | K14: 225 | L14: 771 | M14: 928 | N14: 1021
B15: Total Liabilities | E15: 1291 | F15: 1497 | G15: 1856 | H15: 3370 | I15: 3767 | J15: 4782 | K15: 5382 | L15: 8038 | M15: 8404 | N15: 9367
B16: Fixed Assets -
B17: Land | E17: 0 | F17: 0 | G17: 0 | H17: 34 | I17: 56 | J17: 112 | K17: 149 | L17: 153 | M17: 153 | N17: 154
B18: Building | E18: 356 | F18: 400 | G18: 432 | H18: 489 | I18: 560 | J18: 646 | K18: 835 | L18: 1221 | M18: 4992 | N18: 5718
B19: Plant Machinery | E19: 482 | F19: 546 | G19: 620 | H19: 719 | I19: 799 | J19: 955 | K19: 1145 | L19: 1575 | M19: 1715 | N19: 2052
B20: Equipments | E20: 33 | F20: 32 | G20: 34 | H20: 39 | I20: 42 | J20: 45 | L20: 61 | M20: 53 | N20: 57
B21: Furniture n fittings | E21: 86 | G21: 99 | H21: 116 | I21: 129 | J21: 146 | K21: 171 | L21: 335 | M21: 394 | N21: 472
B22: Vehicles | E22: 40 | F22: 37 | G22: 44 | H22: 60 | I22: 79 | J22: 113 | K22: 153 | L22: 252 | M22: 361 | N22: 497
B23: Intangible Assets | E23: 0 | F23: 0 | G23: 0 | H23: 0 | I23: 0 | J23: 0 | K23: 0 | L23: 1742 | M23: 1677 | N23: 1807
B24: Other fixed assets | E24: 53 | F24: 68 | G24: 81 | H24: 2294 | I24: 2229 | J24: 2644 | K24: 3190 | L24: 3906 | M24: 687 | N24: 981
B25: Gross Block | E25: 1050 | F25: 1173 | G25: 1310 | H25: 3751 | I25: 3895 | J25: 4660 | K25: 5702 | L25: 9245 | M25: 10032 | N25: 11737
B26: Accumulated Depreciation | E26: 250 | F26: 384 | G26: 501 | H26: 1562 | I26: 1750 | J26: 1924 | K26: 2214 | L26: 3061 | M26: 3598 | N26: 4384
B27: CWIP | E27: 61 | F27: 14 | G27: 16 | H27: 41 | I27: 29 | J27: 47 | K27: 184 | L27: 118 | M27: 255 | N27: 160
B28: Investments | E28: 94 | F28: 263 | G28: 181 | H28: 51 | I28: 517 | J28: 927 | K28: 822 | L28: 308 | M28: 176 | N28: 199
B29: Other Assets -
B30: Inventories | E30: 61 | F30: 64 | G30: 77 | H30: 95 | I30: 133 | J30: 161 | K30: 177 | L30: 410 | M30: 406 | N30: 309
B31: Trade receivables + | E31: 16 | F31: 16 | G31: 27 | H31: 17 | I31: 17 | J31: 22 | K31: 29 | L31: 265 | M31: 330 | N31: 375
B32: Cash Equivalents | E32: 35 | F32: 129 | G32: 494 | H32: 656 | I32: 539 | J32: 563 | K32: 257 | L32: 157 | M32: 154 | N32: 235
B33: Loans n Advances | E33: 5 | F33: 5 | G33: 7 | H33: -2 | I33: -3 | J33: -2 | K33: -1 | L33: -1 | M33: -5 | N33: -9
B34: Other asset items | E34: 219 | F34: 216 | G34: 244 | H34: 324 | I34: 389 | J34: 327 | K34: 427 | L34: 597 | M34: 653 | N34: 745
B35: Total Assets | E35: 1291 | F35: 1497 | G35: 1856 | H35: 3370 | I35: 3767 | J35: 4782 | K35: 5382 | L35: 8038 | M35: 8404 | N35: 9367

Sheet Historical Financial Statment
B10: ="Historical Financial Statement"&" - "&'Data Sheet'!B1 -> Historical Financial Statement - JUBILANT FOODWORKS LTD
B11: Particulars | E11: ='Data Sheet'!B16 -> 42825 | F11: ='Data Sheet'!C16 -> 43190 | G11: ='Data Sheet'!D16 -> 43555 | H11: ='Data Sheet'!E16 -> 43921 | I11: ='Data Sheet'!F16 -> 44286 | J11: ='Data Sheet'!G16 -> 44651 | K11: ='Data Sheet'!H16 -> 45016 | L11: ='Data Sheet'!I16 -> 45382 | ... N11: ='Data Sheet'!K16 -> 46112
A12: # | B12: Income Statement
B13: Sales | E13: ='Data Sheet'!B17 -> 2583.39 | F13: ='Data Sheet'!C17 -> 3018.4 | G13: ='Data Sheet'!D17 -> 3563.14 | H13: ='Data Sheet'!E17 -> 3927.27 | I13: ='Data Sheet'!F17 -> 3311.87 | J13: ='Data Sheet'!G17 -> 4396.12 | K13: ='Data Sheet'!H17 -> 5158.25 | L13: ='Data Sheet'!I17 -> 5655.09 | ... N13: ='Data Sheet'!K17 -> 9512.51
B14: Sales Growth | E14: - | F14: =F13/E13-1 -> 0.16838727 | G14: =G13/F13-1 -> 0.1804731 | H14: =H13/G13-1 -> 0.10219357 | I14: =I13/H13-1 -> -0.15669918 | J14: =J13/I13-1 -> 0.32738302 | K14: =K13/J13-1 -> 0.17336424 | L14: =L13/K13-1 -> 0.096319488 | M14: =M13/L13-1 -> 0.43313192 | N14: =N13/M13-1 -> 0.17373333
B16: COGS | E16: =SUM('Data Sheet'!B18,'Data Sheet'!B20:B22)-1*'Data Sheet'!B18 -> 915.97 | F16: =SUM('Data Sheet'!C18,'Data Sheet'!C20:C22)-1*'Data Sheet'!C18 -> 964.41 | G16: =SUM('Data Sheet'!D18,'Data Sheet'!D20:D22)-1*'Data Sheet'!D18 -> 1085.6 | H16: =SUM('Data Sheet'!E18,'Data Sheet'!E20:E22)-1*'Data Sheet'!E18 -> 1216.71 | I16: =SUM('Data Sheet'!F18,'Data Sheet'!F20:F22)-1*'Data Sheet'!F18 -> 896.06 | J16: =SUM('Data Sheet'!G18,'Data Sheet'!G20:G22)-1*'Data Sheet'!G18 -> 1275.45 | K16: =SUM('Data Sheet'!H18,'Data Sheet'!H20:H22)-1*'Data Sheet'!H18 -> 1540.71 | L16: =SUM('Data Sheet'!I18,'Data Sheet'!I20:I22)-1*'Data Sheet'!I18 -> 1784.25 | ... N16: =SUM('Data Sheet'!K18,'Data Sheet'!K20:K22)-1*'Data Sheet'!K18 -> 2234.33
B17: COGS Margin | E17: =E16/E13 -> 0.35456125 | F17: =F16/F13 -> 0.31951034 | G17: =G16/G13 -> 0.30467509 | H17: =H16/H13 -> 0.30981063 | I17: =I16/I13 -> 0.27056014 | J17: =J16/J13 -> 0.29013084 | K17: =K16/K13 -> 0.29868851 | L17: =L16/L13 -> 0.31551222 | ... N17: =N16/N13 -> 0.23488333
B19: Gross Profit | E19: =E13-E16 -> 1667.42 | F19: =F13-F16 -> 2053.99 | G19: =G13-G16 -> 2477.54 | H19: =H13-H16 -> 2710.56 | I19: =I13-I16 -> 2415.81 | J19: =J13-J16 -> 3120.67 | K19: =K13-K16 -> 3617.54 | L19: =L13-L16 -> 3870.84 | ... N19: =N13-N16 -> 7278.18
B20: Gross Margin | E20: =E19/E13 -> 0.64543875 | F20: =F19/F13 -> 0.68048966 | G20: =G19/G13 -> 0.69532491 | H20: =H19/H13 -> 0.69018937 | I20: =I19/I13 -> 0.72943986 | J20: =J19/J13 -> 0.70986916 | K20: =K19/K13 -> 0.70131149 | L20: =L19/L13 -> 0.68448778 | ... N20: =N19/N13 -> 0.76511667
B22: Selling & General Expenses | E22: =SUM('Data Sheet'!B23:B24) -> 792.08 | F22: =SUM('Data Sheet'!C23:C24) -> 846.03 | G22: =SUM('Data Sheet'!D23:D24) -> 988.81 | H22: =SUM('Data Sheet'!E23:E24) -> 844.37 | I22: =SUM('Data Sheet'!F23:F24) -> 647.63 | J22: =SUM('Data Sheet'!G23:G24) -> 1024.41 | K22: =SUM('Data Sheet'!H23:H24) -> 1233.78 | L22: =SUM('Data Sheet'!I23:I24) -> 1370.4 | ... N22: =SUM('Data Sheet'!K23:K24) -> 2260.12
B23: S&G Expenses Margin | E23: =E22/E13 -> 0.30660489 | F23: =F22/F13 -> 0.28029088 | G23: =G22/G13 -> 0.27751085 | H23: =H22/H13 -> 0.21500177 | I23: =I22/I13 -> 0.19554813 | J23: =J22/J13 -> 0.23302594 | K23: =K22/K13 -> 0.23918577 | L23: =L22/L13 -> 0.24233036 | ... N23: =N22/N13 -> 0.23759449
B25: EBITDA | E25: =E19-E22 -> 875.34 | F25: =F19-F22 -> 1207.96 | G25: =G19-G22 -> 1488.73 | H25: =H19-H22 -> 1866.19 | I25: =I19-I22 -> 1768.18 | J25: =J19-J22 -> 2096.26 | K25: =K19-K22 -> 2383.76 | L25: =L19-L22 -> 2500.44 | ... N25: =N19-N22 -> 5018.06
B26: EBITDA Margin | E26: =E25/E13 -> 0.33883386 | F26: =F25/F13 -> 0.40019878 | G26: =G25/G13 -> 0.41781406 | H26: =H25/H13 -> 0.4751876 | I26: =I25/I13 -> 0.53389173 | J26: =J25/J13 -> 0.47684322 | K26: =K25/K13 -> 0.46212572 | L26: =L25/L13 -> 0.44215742 | ... N26: =N25/N13 -> 0.52752218
B28: Interest | E28: ='Data Sheet'!B27 -> 0 | F28: ='Data Sheet'!C27 -> 0 | G28: ='Data Sheet'!D27 -> 0 | H28: ='Data Sheet'!E27 -> 165.24 | I28: ='Data Sheet'!F27 -> 162.7 | J28: ='Data Sheet'!G27 -> 176.09 | K28: ='Data Sheet'!H27 -> 201.23 | L28: ='Data Sheet'!I27 -> 287.77 | ... N28: ='Data Sheet'!K27 -> 435.98
B29: Interest Margin | E29: =E28/E13 -> 0 | F29: =F28/F13 -> 0 | G29: =G28/G13 -> 0 | H29: =H28/H13 -> 0.042075029 | I29: =I28/I13 -> 0.049126324 | J29: =J28/J13 -> 0.040055776 | K29: =K28/K13 -> 0.039011293 | L29: =L28/L13 -> 0.0508869 | ... N29: =N28/N13 -> 0.045832278
B31: Depreciation | E31: ='Data Sheet'!B26 -> 155.43 | F31: ='Data Sheet'!C26 -> 160.11 | G31: ='Data Sheet'!D26 -> 157.45 | H31: ='Data Sheet'!E26 -> 352.28 | I31: ='Data Sheet'!F26 -> 375.4 | J31: ='Data Sheet'!G26 -> 393.05 | K31: ='Data Sheet'!H26 -> 485.89 | L31: ='Data Sheet'!I26 -> 597.96 | ... N31: ='Data Sheet'!K26 -> 958.74
B32: Depreciation Margin | E32: =E31/E13 -> 0.060165132 | F32: =F31/F13 -> 0.053044659 | G32: =G31/G13 -> 0.044188553 | H32: =H31/H13 -> 0.089700988 | I32: =I31/I13 -> 0.11334986 | J32: =J31/J13 -> 0.089408387 | K32: =K31/K13 -> 0.094196675 | L32: =L31/L13 -> 0.10573837 | ... N32: =N31/N13 -> 0.10078728
B34: EBT | E34: =E25-SUM(E28,E31) -> 719.91 | F34: =F25-SUM(F28,F31) -> 1047.85 | G34: =G25-SUM(G28,G31) -> 1331.28 | H34: =H25-SUM(H28,H31) -> 1348.67 | I34: =I25-SUM(I28,I31) -> 1230.08 | J34: =J25-SUM(J28,J31) -> 1527.12 | K34: =K25-SUM(K28,K31) -> 1696.64 | L34: =L25-SUM(L28,L31) -> 1614.71 | ... N34: =N25-SUM(N28,N31) -> 3623.34
B35: EBT Margin | E35: =E34/E13 -> 0.27866873 | F35: =F34/F13 -> 0.34715412 | G35: =G34/G13 -> 0.37362551 | H35: =H34/H13 -> 0.34341158 | I35: =I34/I13 -> 0.37141554 | J35: =J34/J13 -> 0.34737905 | K35: =K34/K13 -> 0.32891775 | L35: =L34/L13 -> 0.28553215 | ... N35: =N34/N13 -> 0.38090262
B37: Tax | E37: ='Data Sheet'!B29 -> 30.5 | F37: ='Data Sheet'!C29 -> 106.83 | G37: ='Data Sheet'!D29 -> 171.7 | H37: ='Data Sheet'!E29 -> 123.99 | I37: ='Data Sheet'!F29 -> 75.65 | J37: ='Data Sheet'!G29 -> 145.18 | K37: ='Data Sheet'!H29 -> 135.7 | L37: ='Data Sheet'!I29 -> 84.97 | ... N37: ='Data Sheet'!K29 -> 154.48
B38: Tax Margin | E38: =E37/E13 -> 0.011806193 | F38: =F37/F13 -> 0.035392923 | G38: =G37/G13 -> 0.048187834 | H38: =H37/H13 -> 0.03157155 | I38: =I37/I13 -> 0.02284208 | J38: =J37/J13 -> 0.033024576 | K38: =K37/K13 -> 0.026307372 | L38: =L37/L13 -> 0.015025402 | ... N38: =N37/N13 -> 0.016239668
B40: Net Profit | E40: =E34-E37 -> 689.41 | F40: =F34-F37 -> 941.02 | G40: =G34-G37 -> 1159.58 | H40: =H34-H37 -> 1224.68 | I40: =I34-I37 -> 1154.43 | J40: =J34-J37 -> 1381.94 | K40: =K34-K37 -> 1560.94 | L40: =L34-L37 -> 1529.74 | ... N40: =N34-N37 -> 3468.86
B41: Net Profit Margin | E41: =E40/E13 -> 0.26686253 | F41: =F40/F13 -> 0.3117612 | G41: =G40/G13 -> 0.32543768 | H41: =H40/H13 -> 0.31184003 | I41: =I40/I13 -> 0.34857346 | J41: =J40/J13 -> 0.31435448 | K41: =K40/K13 -> 0.30261038 | L41: =L40/L13 -> 0.27050675 | ... N41: =N40/N13 -> 0.36466295
B43: Number of Shareholder | E43: ='Data Sheet'!B93 -> 65.94 | F43: ='Data Sheet'!C93 -> 65.98 | G43: ='Data Sheet'!D93 -> 65.98 | H43: ='Data Sheet'!E93 -> 65.98 | I43: ='Data Sheet'!F93 -> 65.98 | J43: ='Data Sheet'!G93 -> 65.98 | K43: ='Data Sheet'!H93 -> 65.98 | L43: ='Data Sheet'!I93 -> 65.98 | ... N43: ='Data Sheet'!K93 -> 65.98
B45: Dividend Amount | E45: ='Data Sheet'!B31 -> 16.49 | F45: ='Data Sheet'!C31 -> 32.99 | G45: ='Data Sheet'!D31 -> 65.98 | H45: ='Data Sheet'!E31 -> 79.18 | I45: ='Data Sheet'!F31 -> 79.18 | J45: ='Data Sheet'!G31 -> 79.18 | K45: ='Data Sheet'!H31 -> 79.18 | L45: ='Data Sheet'!I31 -> 79.18 | ... N45: ='Data Sheet'!K31 -> 79.18
B47: EPS | E47: =E40/E43 -> 10.455111 | F47: =F40/F43 -> 14.262201 | G47: =G40/G43 -> 17.57472 | H47: =H40/H43 -> 18.561382 | I47: =I40/I43 -> 17.496666 | J47: =J40/J43 -> 20.944832 | K47: =K40/K43 -> 23.657775 | L47: =L40/L43 -> 23.184905 | ... N47: =N40/N43 -> 52.574416
B49: Retained Earning | E49: =E40-E45 -> 672.92 | F49: =F40-F45 -> 908.03 | G49: =G40-G45 -> 1093.6 | H49: =H40-H45 -> 1145.5 | I49: =I40-I45 -> 1075.25 | J49: =J40-J45 -> 1302.76 | K49: =K40-K45 -> 1481.76 | L49: =L40-L45 -> 1450.56 | ... N49: =N40-N45 -> 3389.68
B50: Retained Earning % | E50: =E49/E40 -> 0.976081 | F50: =F49/F40 -> 0.9649423 | G50: =G49/G40 -> 0.94310009 | H50: =H49/H40 -> 0.93534638 | I50: =I49/I40 -> 0.93141204 | J50: =J49/J40 -> 0.94270374 | K50: =K49/K40 -> 0.94927416 | L50: =L49/L40 -> 0.94823957 | ... N50: =N49/N40 -> 0.97717406
A53: # | B53: Balance Sheet
B54: Equity Share Capital | E54: ='Data Sheet'!B57 -> 65.95 | F54: ='Data Sheet'!C57 -> 65.98 | G54: ='Data Sheet'!D57 -> 131.97 | H54: ='Data Sheet'!E57 -> 131.97 | I54: ='Data Sheet'!F57 -> 131.97 | J54: ='Data Sheet'!G57 -> 131.97 | K54: ='Data Sheet'!H57 -> 131.97 | L54: ='Data Sheet'!I57 -> 131.97 | ... N54: ='Data Sheet'!K57 -> 131.97
B55: Reserves | E55: ='Data Sheet'!B58 -> 739.35 | F55: ='Data Sheet'!C58 -> 901.75 | G55: ='Data Sheet'!D58 -> 1127.67 | H55: ='Data Sheet'!E58 -> 990.06 | I55: ='Data Sheet'!F58 -> 1294.86 | J55: ='Data Sheet'!G58 -> 1813 | K55: ='Data Sheet'!H58 -> 1905.82 | L55: ='Data Sheet'!I58 -> 2038.67 | ... N55: ='Data Sheet'!K58 -> 2160.13
B56: Borrowings | E56: ='Data Sheet'!B59 -> 0 | F56: ='Data Sheet'!C59 -> 0 | G56: ='Data Sheet'!D59 -> 0 | H56: ='Data Sheet'!E59 -> 1670.06 | I56: ='Data Sheet'!F59 -> 1619.98 | J56: ='Data Sheet'!G59 -> 2106.1 | K56: ='Data Sheet'!H59 -> 2553.74 | L56: ='Data Sheet'!I59 -> 4206.86 | ... N56: ='Data Sheet'!K59 -> 4902.22
B57: Other Liabilities | E57: ='Data Sheet'!B60 -> 485.34 | F57: ='Data Sheet'!C60 -> 529.01 | G57: ='Data Sheet'!D60 -> 596.1 | H57: ='Data Sheet'!E60 -> 577.8 | I57: ='Data Sheet'!F60 -> 719.96 | J57: ='Data Sheet'!G60 -> 730.6 | K57: ='Data Sheet'!H60 -> 790.6 | L57: ='Data Sheet'!I60 -> 1660.04 | ... N57: ='Data Sheet'!K60 -> 2172.32
B58: Total Liabilities | E58: =SUM(E54:E57) -> 1290.64 | F58: =SUM(F54:F57) -> 1496.74 | G58: =SUM(G54:G57) -> 1855.74 | H58: =SUM(H54:H57) -> 3369.89 | I58: =SUM(I54:I57) -> 3766.77 | J58: =SUM(J54:J57) -> 4781.67 | K58: =SUM(K54:K57) -> 5382.13 | L58: =SUM(L54:L57) -> 8037.54 | ... N58: =SUM(N54:N57) -> 9366.64
B60: Net Block | E60: ='Data Sheet'!B62 -> 800.15 | F60: ='Data Sheet'!C62 -> 789.22 | G60: ='Data Sheet'!D62 -> 809.46 | H60: ='Data Sheet'!E62 -> 2188.72 | I60: ='Data Sheet'!F62 -> 2145.5 | J60: ='Data Sheet'!G62 -> 2736.6 | K60: ='Data Sheet'!H62 -> 3488.23 | L60: ='Data Sheet'!I62 -> 6183.85 | ... N60: ='Data Sheet'!K62 -> 7353.09
B61: Capital Work in Progress | E61: ='Data Sheet'!B63 -> 60.77 | F61: ='Data Sheet'!C63 -> 14.22 | G61: ='Data Sheet'!D63 -> 15.72 | H61: ='Data Sheet'!E63 -> 41.17 | I61: ='Data Sheet'!F63 -> 28.55 | J61: ='Data Sheet'!G63 -> 46.55 | K61: ='Data Sheet'!H63 -> 183.79 | L61: ='Data Sheet'!I63 -> 117.76 | ... N61: ='Data Sheet'!K63 -> 160.2
B62: Investments | E62: ='Data Sheet'!B64 -> 93.57 | F62: ='Data Sheet'!C64 -> 263.1 | G62: ='Data Sheet'!D64 -> 180.8 | H62: ='Data Sheet'!E64 -> 51.18 | I62: ='Data Sheet'!F64 -> 516.74 | J62: ='Data Sheet'!G64 -> 926.78 | K62: ='Data Sheet'!H64 -> 821.81 | L62: ='Data Sheet'!I64 -> 308.03 | ... N62: ='Data Sheet'!K64 -> 199.03
B63: Other Assets | E63: ='Data Sheet'!B65-SUM('Data Sheet'!B67:B69) -> 223.94 | F63: ='Data Sheet'!C65-SUM('Data Sheet'!C67:C69) -> 221.31 | G63: ='Data Sheet'!D65-SUM('Data Sheet'!D67:D69) -> 250.97 | H63: ='Data Sheet'!E65-SUM('Data Sheet'!E67:E69) -> 321.58 | I63: ='Data Sheet'!F65-SUM('Data Sheet'!F67:F69) -> 386.87 | J63: ='Data Sheet'!G65-SUM('Data Sheet'!G67:G69) -> 325.15 | K63: ='Data Sheet'!H65-SUM('Data Sheet'!H67:H69) -> 425.66 | L63: ='Data Sheet'!I65-SUM('Data Sheet'!I67:I69) -> 595.99 | ... N63: ='Data Sheet'!K65-SUM('Data Sheet'!K67:K69) -> 736.14
B64: Total Non Current Assets | E64: =SUM(E60:E63) -> 1178.43 | F64: =SUM(F60:F63) -> 1287.85 | G64: =SUM(G60:G63) -> 1256.95 | H64: =SUM(H60:H63) -> 2602.65 | I64: =SUM(I60:I63) -> 3077.66 | J64: =SUM(J60:J63) -> 4035.08 | K64: =SUM(K60:K63) -> 4919.49 | L64: =SUM(L60:L63) -> 7205.63 | ... N64: =SUM(N60:N63) -> 8448.46
B66: Receivables | E66: ='Data Sheet'!B67 -> 16.1 | F66: ='Data Sheet'!C67 -> 15.65 | G66: ='Data Sheet'!D67 -> 27.44 | H66: ='Data Sheet'!E67 -> 16.64 | I66: ='Data Sheet'!F67 -> 16.8 | J66: ='Data Sheet'!G67 -> 22.05 | K66: ='Data Sheet'!H67 -> 28.73 | L66: ='Data Sheet'!I67 -> 265.07 | ... N66: ='Data Sheet'!K67 -> 374.78
...

Sheet WACC
B9: Note:- All detail are given in INR(cr.) otherwise it mention by Symbol
B11: Peer Company
F12: Market | H12: Debt / | I12: Debt / | J12: Levered | K12: Unlevered
B13: Name of the Comp | D13: Country | E13: Total Debt | F13: Capitalization | G13: Tax Rate | H13: Equity | I13: Capital | J13: Beta 2 | K13: Beta 3
B14: Jubilant Food. | D14: India | E14: 4902.22 | F14: 28023.62 | G14: 0.3 | H14: =E14/F14 -> 0.17493172 | I14: =E14/SUM(E14:F14) -> 0.14888671 | J14: 1.24 | K14: =J14/(1+(1-G14)*I14) -> 1.1229639
B15: Travel Food | D15: India | E15: 244.79 | F15: 15634.7 | G15: 0.3 | H15: =E15/F15 -> 0.01565684 | I15: =E15/SUM(E15:F15) -> 0.015415482 | J15: 0.54 | K15: =J15/(1+(1-G15)*I15) -> 0.53423516
B16: Devyani Intl. | D16: India | E16: 3833.15 | F16: 14980.22 | G16: 0.3 | H16: =E16/F16 -> 0.25588075 | I16: =E16/SUM(E16:F16) -> 0.20374606 | J16: 1.3 | K16: =J16/(1+(1-G16)*I16) -> 1.1377338
B17: Westlife Food | D17: India | E17: 1804.79 | F17: 8981.91 | G17: 0.3 | H17: =E17/F17 -> 0.2009361 | I17: =E17/SUM(E17:F17) -> 0.16731623 | J17: 1.03 | K17: =J17/(1+(1-G17)*I17) -> 0.92201263
B18: Restaurant Brand | D18: India | E18: 1967 | F18: 6534.6 | G18: 0.3 | H18: =E18/F18 -> 0.30101307 | I18: =E18/SUM(E18:F18) -> 0.23136821 | J18: 0.64 | K18: =J18/(1+(1-G18)*I18) -> 0.55079455
F20: Average | G20: =AVERAGE(G14:G18) -> 0.3 | H20: =AVERAGE(H14:H18) -> 0.1896837 | I20: =AVERAGE(I14:I18) -> 0.15334654 | J20: =AVERAGE(J14:J18) -> 0.95 | K20: =AVERAGE(K14:K18) -> 0.85354802
F21: Median | G21: =MEDIAN(G14:G18) -> 0.3 | H21: =MEDIAN(H14:H18) -> 0.2009361 | I21: =MEDIAN(I14:I18) -> 0.16731623 | J21: =MEDIAN(J14:J18) -> 1.03 | K21: =MEDIAN(K14:K18) -> 0.92201263
B24: Cost of Debt | H24: Cost of Equity
B26: Pre Tax Cost of Debt | F26: =MEDIAN('Historical Financial Statment'!$E$28:$N$28)/WACC!E14 -> 0.034813819 | H26: Risk Free Rate | K26: 0.0735
B27: Tax Rate | F27: =G21 -> 0.3 | H27: Equity Resarch Premium | K27: =12.77%-K26 -> 0.0542
B28: Post Tax Cost of Debt | F28: =F26*(1-F27) -> 0.024369673 | H28: Levered Beta | K28: =K37 -> 0.80831838
H29: Cost of Equity | K29: =K26+K27*K28 -> 0.11731086
B32: Market Structured | H32: Levered Beta 1
E34: Current | F34: Target | H34: Market comp of Unlevered Beta | K34: =K21 -> 0.92201263
B35: Total Debt | D35: =E14 -> 4902.22 | E35: =D35/D37 -> 0.14888671 | F35: =I21 -> 0.16731623 | H35: Target Debt /Equity | K35: =F39 -> 0.2009361
B36: Market Capitalization | D36: =F14 -> 28023.62 | E36: =D36/D37 -> 0.85111329 | F36: =F37-F35 -> 0.83268377 | H36: Tax Rate | K36: =F27 -> 0.3
B37: Total Capital | D37: =SUM(D35:D36) -> 32925.84 | E37: =SUM(E35:E36) -> 1 | F37: =E37 -> 1 | H37: Levered Beta 1 | K37: =K34/(1+(1-K36)*K35) -> 0.80831838
D39: Debt /Equity | E39: =E35/E36 -> 0.17493172 | F39: =F35/F36 -> 0.2009361
H40: Weighted Average Cost of Capital
K42: Total Cost | L42: Total Weighted
H43: Cost of Equity | K43: =K29 -> 0.11731086 | L43: =F36 -> 0.83268377
H44: Cost Of Debt | K44: =F28 -> 0.024369673 | L44: =F35 -> 0.16731623
H45: Weighted Average Cost of Capital | L45: =(K44*L44)+(K43*L43) -> 0.10176029

Sheet Growth Rate
B9: Calculation of ROIC | F9: ='Data Sheet'!B56 -> 42825 | G9: ='Data Sheet'!C56 -> 43190 | H9: ='Data Sheet'!D56 -> 43555 | I9: ='Data Sheet'!E56 -> 43921 | J9: ='Data Sheet'!F56 -> 44286 | K9: ='Data Sheet'!G56 -> 44651 | L9: ='Data Sheet'!H56 -> 45016 | M9: ='Data Sheet'!I56 -> 45382 | ... O9: ='Data Sheet'!K56 -> 46112
B11: Current Assets
B12: ='Data Collection'!B30 -> Inventories | F12: ='Data Collection'!E30 -> 61 | G12: ='Data Collection'!F30 -> 64 | H12: ='Data Collection'!G30 -> 77 | I12: ='Data Collection'!H30 -> 95 | J12: ='Data Collection'!I30 -> 133 | K12: ='Data Collection'!J30 -> 161 | L12: ='Data Collection'!K30 -> 177 | M12: ='Data Collection'!L30 -> 410 | ... O12: ='Data Collection'!N30 -> 309
B13: ='Data Collection'!B31 -> Trade receivables + | F13: ='Data Collection'!E31 -> 16 | G13: ='Data Collection'!F31 -> 16 | H13: ='Data Collection'!G31 -> 27 | I13: ='Data Collection'!H31 -> 17 | J13: ='Data Collection'!I31 -> 17 | K13: ='Data Collection'!J31 -> 22 | L13: ='Data Collection'!K31 -> 29 | M13: ='Data Collection'!L31 -> 265 | ... O13: ='Data Collection'!N31 -> 375
B14: ='Data Collection'!B33 -> Loans n Advances | F14: ='Data Collection'!E33 -> 5 | G14: ='Data Collection'!F33 -> 5 | H14: ='Data Collection'!G33 -> 7 | I14: ='Data Collection'!H33 -> -2 | J14: ='Data Collection'!I33 -> -3 | K14: ='Data Collection'!J33 -> -2 | L14: ='Data Collection'!K33 -> -1 | M14: ='Data Collection'!L33 -> -1 | ... O14: ='Data Collection'!N33 -> -9
B15: ='Data Collection'!B34 -> Other asset items | F15: ='Data Collection'!E34 -> 219 | G15: ='Data Collection'!F34 -> 216 | H15: ='Data Collection'!G34 -> 244 | I15: ='Data Collection'!H34 -> 324 | J15: ='Data Collection'!I34 -> 389 | K15: ='Data Collection'!J34 -> 327 | L15: ='Data Collection'!K34 -> 427 | M15: ='Data Collection'!L34 -> 597 | ... O15: ='Data Collection'!N34 -> 745
B16: Total Current Assets | F16: =SUM(F12:F15) -> 301 | G16: =SUM(G12:G15) -> 301 | H16: =SUM(H12:H15) -> 355 | I16: =SUM(I12:I15) -> 434 | J16: =SUM(J12:J15) -> 536 | K16: =SUM(K12:K15) -> 508 | L16: =SUM(L12:L15) -> 632 | M16: =SUM(M12:M15) -> 1271 | ... O16: =SUM(O12:O15) -> 1420
B18: Current Liabilities
B19: ='Data Collection'!B12 -> Trade Payables | F19: ='Data Collection'!E12 -> 314 | G19: ='Data Collection'!F12 -> 389 | H19: ='Data Collection'!G12 -> 421 | I19: ='Data Collection'!H12 -> 447 | J19: ='Data Collection'!I12 -> 533 | K19: ='Data Collection'!J12 -> 537 | L19: ='Data Collection'!K12 -> 561 | M19: ='Data Collection'!L12 -> 790 | ... O19: ='Data Collection'!N12 -> 1036
B20: ='Data Collection'!B13 -> Advance from Customers | F20: ='Data Collection'!E13 -> 0 | G20: ='Data Collection'!F13 -> 0 | H20: ='Data Collection'!G13 -> 0 | I20: ='Data Collection'!H13 -> 1 | J20: ='Data Collection'!I13 -> 2 | K20: ='Data Collection'!J13 -> 4 | L20: ='Data Collection'!K13 -> 4 | M20: ='Data Collection'!L13 -> 26 | ... O20: ='Data Collection'!N13 -> 20
B21: ='Data Collection'!B14 -> Other liability items | F21: ='Data Collection'!E14 -> 171 | G21: ='Data Collection'!F14 -> 140 | H21: ='Data Collection'!G14 -> 173 | I21: ='Data Collection'!H14 -> 119 | J21: ='Data Collection'!I14 -> 176 | K21: ='Data Collection'!J14 -> 180 | L21: ='Data Collection'!K14 -> 225 | M21: ='Data Collection'!L14 -> 771 | ... O21: ='Data Collection'!N14 -> 1021
B22: Total Current Liabilities | F22: =SUM(F19:F21) -> 485 | G22: =SUM(G19:G21) -> 529 | H22: =SUM(H19:H21) -> 594 | I22: =SUM(I19:I21) -> 567 | J22: =SUM(J19:J21) -> 711 | K22: =SUM(K19:K21) -> 721 | L22: =SUM(L19:L21) -> 790 | M22: =SUM(M19:M21) -> 1587 | ... O22: =SUM(O19:O21) -> 2077
B24: Net Working Capital | F24: =F16-F22 -> -184 | G24: =G16-G22 -> -228 | H24: =H16-H22 -> -239 | I24: =I16-I22 -> -133 | J24: =J16-J22 -> -175 | K24: =K16-K22 -> -213 | L24: =L16-L22 -> -158 | M24: =M16-M22 -> -316 | ... O24: =O16-O22 -> -657
B26: Non Current Assets
B27: ='Data Collection'!B17 -> Land | F27: ='Data Collection'!E17 -> 0 | G27: ='Data Collection'!F17 -> 0 | H27: ='Data Collection'!G17 -> 0 | I27: ='Data Collection'!H17 -> 34 | J27: ='Data Collection'!I17 -> 56 | K27: ='Data Collection'!J17 -> 112 | L27: ='Data Collection'!K17 -> 149 | M27: ='Data Collection'!L17 -> 153 | ... O27: ='Data Collection'!N17 -> 154
B28: ='Data Collection'!B18 -> Building | F28: ='Data Collection'!E18 -> 356 | G28: ='Data Collection'!F18 -> 400 | H28: ='Data Collection'!G18 -> 432 | I28: ='Data Collection'!H18 -> 489 | J28: ='Data Collection'!I18 -> 560 | K28: ='Data Collection'!J18 -> 646 | L28: ='Data Collection'!K18 -> 835 | M28: ='Data Collection'!L18 -> 1221 | ... O28: ='Data Collection'!N18 -> 5718
B29: ='Data Collection'!B19 -> Plant Machinery | F29: ='Data Collection'!E19 -> 482 | G29: ='Data Collection'!F19 -> 546 | H29: ='Data Collection'!G19 -> 620 | I29: ='Data Collection'!H19 -> 719 | J29: ='Data Collection'!I19 -> 799 | K29: ='Data Collection'!J19 -> 955 | L29: ='Data Collection'!K19 -> 1145 | M29: ='Data Collection'!L19 -> 1575 | ... O29: ='Data Collection'!N19 -> 2052
B30: ='Data Collection'!B20 -> Equipments | F30: ='Data Collection'!E20 -> 33 | G30: ='Data Collection'!F20 -> 32 | H30: ='Data Collection'!G20 -> 34 | I30: ='Data Collection'!H20 -> 39 | J30: ='Data Collection'!I20 -> 42 | K30: ='Data Collection'!J20 -> 45 | L30: ='Data Collection'!K20 -> 0 | M30: ='Data Collection'!L20 -> 61 | ... O30: ='Data Collection'!N20 -> 57
B31: ='Data Collection'!B21 -> Furniture n fittings | F31: ='Data Collection'!E21 -> 86 | G31: ='Data Collection'!F21 -> 0 | H31: ='Data Collection'!G21 -> 99 | I31: ='Data Collection'!H21 -> 116 | J31: ='Data Collection'!I21 -> 129 | K31: ='Data Collection'!J21 -> 146 | L31: ='Data Collection'!K21 -> 171 | M31: ='Data Collection'!L21 -> 335 | ... O31: ='Data Collection'!N21 -> 472
B32: ='Data Collection'!B22 -> Vehicles | F32: ='Data Collection'!E22 -> 40 | G32: ='Data Collection'!F22 -> 37 | H32: ='Data Collection'!G22 -> 44 | I32: ='Data Collection'!H22 -> 60 | J32: ='Data Collection'!I22 -> 79 | K32: ='Data Collection'!J22 -> 113 | L32: ='Data Collection'!K22 -> 153 | M32: ='Data Collection'!L22 -> 252 | ... O32: ='Data Collection'!N22 -> 497
B33: ='Data Collection'!B23 -> Intangible Assets | F33: ='Data Collection'!E23 -> 0 | G33: ='Data Collection'!F23 -> 0 | H33: ='Data Collection'!G23 -> 0 | I33: ='Data Collection'!H23 -> 0 | J33: ='Data Collection'!I23 -> 0 | K33: ='Data Collection'!J23 -> 0 | L33: ='Data Collection'!K23 -> 0 | M33: ='Data Collection'!L23 -> 1742 | ... O33: ='Data Collection'!N23 -> 1807
B34: ='Data Collection'!B24 -> Other fixed assets | F34: ='Data Collection'!E24 -> 53 | G34: ='Data Collection'!F24 -> 68 | H34: ='Data Collection'!G24 -> 81 | I34: ='Data Collection'!H24 -> 2294 | J34: ='Data Collection'!I24 -> 2229 | K34: ='Data Collection'!J24 -> 2644 | L34: ='Data Collection'!K24 -> 3190 | M34: ='Data Collection'!L24 -> 3906 | ... O34: ='Data Collection'!N24 -> 981
B35: Gross Block | F35: =SUM(F27:F34) -> 1050 | G35: =SUM(G27:G34) -> 1083 | H35: =SUM(H27:H34) -> 1310 | I35: =SUM(I27:I34) -> 3751 | J35: =SUM(J27:J34) -> 3894 | K35: =SUM(K27:K34) -> 4661 | L35: =SUM(L27:L34) -> 5643 | M35: =SUM(M27:M34) -> 9245 | ... O35: =SUM(O27:O34) -> 11738
B36: Accumulated Depreciation | F36: ='Data Collection'!E26 -> 250 | G36: ='Data Collection'!F26 -> 384 | H36: ='Data Collection'!G26 -> 501 | I36: ='Data Collection'!H26 -> 1562 | J36: ='Data Collection'!I26 -> 1750 | K36: ='Data Collection'!J26 -> 1924 | L36: ='Data Collection'!K26 -> 2214 | M36: ='Data Collection'!L26 -> 3061 | ... O36: ='Data Collection'!N26 -> 4384
B37: Net Non Current Assets | F37: =F35-F36 -> 800 | G37: =G35-G36 -> 699 | H37: =H35-H36 -> 809 | I37: =I35-I36 -> 2189 | J37: =J35-J36 -> 2144 | K37: =K35-K36 -> 2737 | L37: =L35-L36 -> 3429 | M37: =M35-M36 -> 6184 | ... O37: =O35-O36 -> 7354
B39: Reinvested Capital | F39: =F24+F37 -> 616 | G39: =G24+G37 -> 471 | H39: =H24+H37 -> 570 | I39: =I24+I37 -> 2056 | J39: =J24+J37 -> 1969 | K39: =K24+K37 -> 2524 | L39: =L24+L37 -> 3271 | M39: =M24+M37 -> 5868 | ... O39: =O24+O37 -> 6697
B41: Calculation of NOPAT | F41: =F9 -> 42825 | G41: =G9 -> 43190 | H41: =H9 -> 43555 | I41: =I9 -> 43921 | J41: =J9 -> 44286 | K41: =K9 -> 44651 | L41: =L9 -> 45016 | M41: =M9 -> 45382 | ... O41: =O9 -> 46112
B42: EBIT | F42: ='Historical Financial Statment'!E25-'Historical Financial Statment'!E31 -> 719.91 | G42: ='Historical Financial Statment'!F25-'Historical Financial Statment'!F31 -> 1047.85 | H42: ='Historical Financial Statment'!G25-'Historical Financial Statment'!G31 -> 1331.28 | I42: ='Historical Financial Statment'!H25-'Historical Financial Statment'!H31 -> 1513.91 | J42: ='Historical Financial Statment'!I25-'Historical Financial Statment'!I31 -> 1392.78 | K42: ='Historical Financial Statment'!J25-'Historical Financial Statment'!J31 -> 1703.21 | L42: ='Historical Financial Statment'!K25-'Historical Financial Statment'!K31 -> 1897.87 | M42: ='Historical Financial Statment'!L25-'Historical Financial Statment'!L31 -> 1902.48 | ... O42: ='Historical Financial Statment'!N25-'Historical Financial Statment'!N31 -> 4059.32
B43: Tax Rate | F43: =WACC!$G$21 -> 0.3 | G43: =WACC!$G$21 -> 0.3 | H43: =WACC!$G$21 -> 0.3 | I43: =WACC!$G$21 -> 0.3 | J43: =WACC!$G$21 -> 0.3 | K43: =WACC!$G$21 -> 0.3 | L43: =WACC!$G$21 -> 0.3 | M43: =WACC!$G$21 -> 0.3 | ... O43: =WACC!$G$21 -> 0.3
B44: NOPAT | F44: =F42*(1-F43) -> 503.937 | G44: =G42*(1-G43) -> 733.495 | H44: =H42*(1-H43) -> 931.896 | I44: =I42*(1-I43) -> 1059.737 | J44: =J42*(1-J43) -> 974.946 | K44: =K42*(1-K43) -> 1192.247 | L44: =L42*(1-L43) -> 1328.509 | M44: =M42*(1-M43) -> 1331.736 | ... O44: =O42*(1-O43) -> 2841.524
A46: # | B46: ROIC | F46: =F44/F39 -> 0.81807955 | G46: =G44/G39 -> 1.5573142 | H46: =H44/H39 -> 1.6349053 | I46: =I44/I39 -> 0.51543628 | J46: =J44/J39 -> 0.49514779 | K46: =K44/K39 -> 0.4723641 | L46: =L44/L39 -> 0.40614766 | M46: =M44/M39 -> 0.22694888 | ... O46: =O44/O39 -> 0.42429804
B49: Calculation of Reinvestment Rate | F49: =F41 -> 42825 | G49: =G41 -> 43190 | H49: =H41 -> 43555 | I49: =I41 -> 43921 | J49: =J41 -> 44286 | K49: =K41 -> 44651 | L49: =L41 -> 45016 | M49: =M41 -> 45382 | ... O49: =O41 -> 46112
B51: Net Capex | F51: =-('Historical Financial Statment'!E86+'Historical Financial Statment'!E87) -> 200 | G51: =-('Historical Financial Statment'!F86+'Historical Financial Statment'!F87) -> 116 | H51: =-('Historical Financial Statment'!G86+'Historical Financial Statment'!G87) -> 166 | I51: =-('Historical Financial Statment'!H86+'Historical Financial Statment'!H87) -> 288 | J51: =-('Historical Financial Statment'!I86+'Historical Financial Statment'!I87) -> 218 | K51: =-('Historical Financial Statment'!J86+'Historical Financial Statment'!J87) -> 456 | L51: =-('Historical Financial Statment'!K86+'Historical Financial Statment'!K87) -> 838 | M51: =-('Historical Financial Statment'!L86+'Historical Financial Statment'!L87) -> 848 | ... O51: =-('Historical Financial Statment'!N86+'Historical Financial Statment'!N87) -> 1005
B52: Change in Working Capital | F52: 0 | G52: =G24-F24 -> -44 | H52: =H24-G24 -> -11 | I52: =I24-H24 -> 106 | J52: =J24-I24 -> -42 | K52: =K24-J24 -> -38 | L52: =L24-K24 -> 55 | M52: =M24-L24 -> -158 | N52: =N24-M24 -> -149 | O52: =O24-N24 -> -192
B53: Reinvestment Rate | F53: =F51+F52 -> 200 | G53: =G51+G52 -> 72 | H53: =H51+H52 -> 155 | I53: =I51+I52 -> 394 | J53: =J51+J52 -> 176 | K53: =K51+K52 -> 418 | L53: =L51+L52 -> 893 | M53: =M51+M52 -> 690 | ... O53: =O51+O52 -> 813
B54: Reinvestment Rate | F54: =F53/F44 -> 0.39687501 | G54: =G53/G44 -> 0.098160178 | H54: =H53/H44 -> 0.16632757 | I54: =I53/I44 -> 0.37179036 | J54: =J53/J44 -> 0.18052282 | K54: =K53/K44 -> 0.35059849 | L54: =L53/L44 -> 0.67218212 | M54: =M53/M44 -> 0.51812071 | ... O54: =O53/O44 -> 0.28611407
A55: #
B56: Calculation of Intrinsic Growth Rate | F56: =F49 -> 42825 | G56: =G49 -> 43190 | H56: =H49 -> 43555 | I56: =I49 -> 43921 | J56: =J49 -> 44286 | K56: =K49 -> 44651 | L56: =L49 -> 45016 | M56: =M49 -> 45382 | ... O56: =O49 -> 46112
B58: =B46 -> ROIC | F58: =F46 -> 0.81807955 | G58: =G46 -> 1.5573142 | H58: =H46 -> 1.6349053 | I58: =I46 -> 0.51543628 | J58: =J46 -> 0.49514779 | K58: =K46 -> 0.4723641 | L58: =L46 -> 0.40614766 | M58: =M46 -> 0.22694888 | ... O58: =O46 -> 0.42429804
B59: =B54 -> Reinvestment Rate | F59: =F54 -> 0.39687501 | G59: =G54 -> 0.098160178 | H59: =H54 -> 0.16632757 | I59: =I54 -> 0.37179036 | J59: =J54 -> 0.18052282 | K59: =K54 -> 0.35059849 | L59: =L54 -> 0.67218212 | M59: =M54 -> 0.51812071 | ... O59: =O54 -> 0.28611407
...

Sheet DCF Valuation
B9: Calculation of PV OF FCFF | F9: ='Data Collection'!N2 -> 46082 | G9: =F9+365 -> 46447 | H9: =G9+366 -> 46813 | I9: =H9+366 -> 47179 | J9: =I9+366 -> 47545 | K9: =J9+366 -> 47911
B11: NOPAT | F11: ='Growth Rate'!$O$44 -> 2841.524 | G11: =F11*(1+$D$18) -> 3186.4783 | H11: =G11*(1+$D$18) -> 3573.3093 | I11: =H11*(1+$D$18) -> 4007.1006 | J11: =I11*(1+$D$18) -> 4493.5531 | K11: =J11*(1+$D$18) -> 5039.0599
B12: Less - Reinvestment Rate | F12: ='Growth Rate'!$O$54 -> 0.28611407
B13: FCFF | F13: =F11*(1-F12) -> 2028.524 | G13: =G11*(1-G12) -> 3186.4783 | H13: =H11*(1-H12) -> 3573.3093 | I13: =I11*(1-I12) -> 4007.1006 | J13: =J11*(1-J12) -> 4493.5531 | K13: =K11*(1-K12) -> 5039.0599
B14: Monthly Period Exemptions | G14: 0.5 | H14: =G14+1 -> 1.5 | I14: =H14+1 -> 2.5 | J14: =I14+1 -> 3.5 | K14: =J14+1 -> 4.5
B15: Discounted Factor | F15: =1/(1+$D$19)^F14 -> 1 | G15: =1/(1+$D$19)^G14 -> 0.95270061 | H15: =1/(1+$D$19)^H14 -> 0.8647077 | I15: =1/(1+$D$19)^I14 -> 0.78484196 | J15: =1/(1+$D$19)^J14 -> 0.71235274 | K15: =1/(1+$D$19)^K14 -> 0.64655874
B16: PV of FCFF | G16: =G13*G15 -> 3035.7598 | H16: =H13*H15 -> 3089.868 | I16: =I13*I15 -> 3144.9407 | J16: =J13*J15 -> 3200.9949 | K16: =K13*K15 -> 3258.0482
B18: Growth Rate | D18: ='Growth Rate'!O63 -> 0.12139764
B19: WACC | D19: =WACC!$L$45 -> 0.10176029
B20: Terminal Growth Rate | D20: 0.055
B22: Calculation of Terminal Value | F22: Sensitivity Analysis
B23: fcff(1-n) | D23: =K11*(1+D18) -> 5650.7899 | F23: =D41 -> 1399.7041 | G23: 0.1 | H23: 0.1018 | I23: 0.12 | J23: 0.13
B24: WACC | D24: =D19 -> 0.10176029 | F24: 0.03 | G24: 1006.5522 | H24: 986.72073 | I24: 830.76215 | J24: 769.23563
B25: =B20 -> Terminal Growth Rate | D25: =D20 -> 0.055 | F25: 0.04 | G25: 1138.3947 | H25: 1111.5142 | I25: 907.67029 | J25: 830.76215
B26: Terminal Value | D26: =D23/(D24-D25) -> 120845.92 | F26: 0.055 | G26: 1446.0273 | H26: 1398.6992 | I26: 1067.4026 | J26: 953.81518
F27: 0.07 | G27: 2061.2925 | H27: 1956.8135 | I27: 1322.9743 | J27: 1138.3947
B29: Calculation of Equity Value per Share
B30: PV of FCFF | D30: =SUM(G16:K16) -> 15729.612
B31: PV of Terminal Value | D31: =D26*K15 -> 78133.983
B32: PV of Operating Assets | D32: =SUM(D30:D31) -> 93863.595
B34: Add - Cash | D34: ='Data Sheet'!K69 -> 234.88
B35: Less - Debt | D35: ='Data Collection'!N6+'Data Collection'!N7 -> 1746
B37: PV of Equity Value | D37: =D32+D34-D35 -> 92352.475
B39: Number of Shareholders | D39: ='Data Sheet'!K93 -> 65.98
B41: Equity Value per Share | D41: =D37/D39 -> 1399.7041
B43: CPM | D43: 422.5
B45: Discount | D45: =D41/D43 -> 3.3129091

Sheet Comp value
B10: Company | C10: Ticker | D10: Share Price | E10: Share Outstanding | F10: Total Debt | G10: Market Capitalization | H10: Enterprise Value | J10: EBITDA | K10: Revenue | L10: Net Income | N10: EV/EBITDA | O10: EV/ Revenue | P10: P/E
B12: ='COMP DATA'!C3 -> Jubilant Food. | D12: ='COMP DATA'!D3 -> 422.1 | E12: ='COMP DATA'!E3 -> 65.98 | F12: ='COMP DATA'!F3 -> 4902.22 | G12: ='COMP DATA'!G3 -> 27852.08 | H12: ='COMP DATA'!H3 -> 32519.42 | J12: ='COMP DATA'!I3 -> 2031.02 | K12: ='COMP DATA'!J3 -> 9838.46 | L12: ='COMP DATA'!K3 -> 449.93 | N12: =H12/J12 -> 16.011374 | O12: =H12/K12 -> 3.3053364 | P12: =G12/L12 -> 61.90314
B13: ='COMP DATA'!C4 -> Travel Food | D13: ='COMP DATA'!D4 -> 1200.6 | E13: ='COMP DATA'!E4 -> 13.17 | F13: ='COMP DATA'!F4 -> 244.79 | G13: ='COMP DATA'!G4 -> 15813.82 | H13: ='COMP DATA'!H4 -> 15999.25 | J13: ='COMP DATA'!I4 -> 854.83 | K13: ='COMP DATA'!J4 -> 1724.96 | L13: ='COMP DATA'!K4 -> 486.11 | N13: =H13/J13 -> 18.716294 | O13: =H13/K13 -> 9.2751426 | P13: =G13/L13 -> 32.531361
B14: ='COMP DATA'!C5 -> Devyani Intl. | D14: ='COMP DATA'!D5 -> 121.5 | E14: ='COMP DATA'!E5 -> 123.29 | F14: ='COMP DATA'!F5 -> 3833.15 | G14: ='COMP DATA'!G5 -> 14980.21 | H14: ='COMP DATA'!H5 -> 18318.56 | J14: ='COMP DATA'!I5 -> 948.37 | K14: ='COMP DATA'!J5 -> 5835.03 | L14: ='COMP DATA'!K5 -> -27.66 | N14: =H14/J14 -> 19.315837 | O14: =H14/K14 -> 3.1394115 | P14: =G14/L14 -> -541.58388
B15: ='COMP DATA'!C6 -> Westlife Food | D15: ='COMP DATA'!D6 -> 581.3 | E15: ='COMP DATA'!E6 -> 15.59 | F15: ='COMP DATA'!F6 -> 1804.79 | G15: ='COMP DATA'!G6 -> 9064.57 | H15: ='COMP DATA'!H6 -> 10852.43 | J15: ='COMP DATA'!I6 -> 375.65 | K15: ='COMP DATA'!J6 -> 2703.57 | L15: ='COMP DATA'!K6 -> 31.7 | N15: =H15/J15 -> 28.889738 | O15: =H15/K15 -> 4.014111 | P15: =G15/L15 -> 285.94858
B16: ='COMP DATA'!C7 -> Restaurant Brand | D16: ='COMP DATA'!D7 -> 92.32 | E16: ='COMP DATA'!E7 -> 71.22 | F16: ='COMP DATA'!F7 -> 1967 | G16: ='COMP DATA'!G7 -> 6575.21 | H16: ='COMP DATA'!H7 -> 8483.3 | J16: ='COMP DATA'!I7 -> 402.11 | K16: ='COMP DATA'!J7 -> 2947.53 | L16: ='COMP DATA'!K7 -> -191.72 | N16: =H16/J16 -> 21.096964 | O16: =H16/K16 -> 2.8781047 | P16: =G16/L16 -> -34.2959
B18: High | N18: =MAX(N12:N16) -> 28.889738 | O18: =MAX(O12:O16) -> 9.2751426 | P18: =MAX(P12:P16) -> 285.94858
B19: 75 th Percentile | N19: =QUARTILE(N12:N16,) -> 16.011374 | O19: =QUARTILE(O12:O16,) -> 2.8781047 | P19: =QUARTILE(P12:P16,) -> -541.58388
B20: Average | N20: =AVERAGE(N12:N16) -> 20.806041 | O20: =AVERAGE(O12:O16) -> 4.5224212 | P20: =AVERAGE(P12:P16) -> -39.099339
B21: Median | N21: =MEDIAN(N12:N16) -> 19.315837 | O21: =MEDIAN(O12:O16) -> 3.3053364 | P21: =MEDIAN(P12:P16) -> 32.531361
B22: 25 th Percentile | N22: =QUARTILE(N12:N16,) -> 16.011374 | O22: =QUARTILE(O12:O16,) -> 2.8781047 | P22: =QUARTILE(P12:P16,) -> -541.58388
B23: Low | N23: =MIN(N12:N16) -> 16.011374 | O23: =MIN(O12:O16) -> 2.8781047 | P23: =MIN(P12:P16) -> -541.58388
B25: Calculation of Implied Equity value per Share | N25: =N10 -> EV/EBITDA | O25: =O10 -> EV/ Revenue | P25: =P10 -> P/E
B26: Implied Market Capitalization | N26: =N28-N27 -> 34328.631 | O26: =O28-O27 -> 27617.2 | P26: =P28-P27 -> 9734.6154
B27: Total Debt | N27: =$F$12 -> 4902.22 | O27: =$F$12 -> 4902.22 | P27: =$F$12 -> 4902.22
B28: Implied Enterprise Value | N28: =N21*J12 -> 39230.851 | O28: =O21*K12 -> 32519.42 | P28: =P21*L12 -> 14636.835
B29: Number of Shares | N29: ='DCF Valuation'!$D$39 -> 65.98 | O29: ='DCF Valuation'!$D$39 -> 65.98 | P29: ='DCF Valuation'!$D$39 -> 65.98
B30: Implied Equity value per Share | N30: =N28/N29 -> 594.587 | O30: =O28/O29 -> 492.86784 | P30: =P28/P29 -> 221.83746

Sheet Football Field Analysis
I9: Football Field Analysis
K10: Open Low | L10: Low | M10: Open High | N10: High
I11: Comparable Price | K11: ='Comp value'!$P$30 -> 221.83746 | L11: ='Comp value'!$P$30 -> 221.83746 | M11: ='Comp value'!$N$30 -> 594.587 | N11: ='Comp value'!$N$30 -> 594.587
I12: DCF Bull | K12: ='DCF Valuation'!$G$24 -> 1006.5522 | L12: ='DCF Valuation'!$G$24 -> 1006.5522 | M12: ='DCF Valuation'!$G$27 -> 2061.2925 | N12: ='DCF Valuation'!$G$27 -> 2061.2925
I13: DCF Base | K13: ='DCF Valuation'!$H$24 -> 986.72073 | L13: ='DCF Valuation'!$H$24 -> 986.72073 | M13: ='DCF Valuation'!$H$27 -> 1956.8135 | N13: ='DCF Valuation'!$H$27 -> 1956.8135
I14: DCF Bear | K14: ='DCF Valuation'!$J$24 -> 769.23563 | L14: ='DCF Valuation'!$J$24 -> 769.23563 | M14: ='DCF Valuation'!$J$27 -> 1138.3947 | N14: ='DCF Valuation'!$J$27 -> 1138.3947
